Workbook
Name Slicer_AI_Adoption_Level: #N/A
Name Slicer_Industry_Sector: #N/A
Name Slicer_Industry_Sector1: #N/A
Name Slicer_Months__Date_Joined: #N/A
Name Slicer_Region: #N/A
Name Slicer_Region1: #N/A
Name Slicer_Region2: #N/A

Sheet Dataset
A1: Customer Age | B1: Region | C1: Date Joined | D1: End Date | E1: Monthly Subscription ($) | F1: Tenure (Months) | G1: Total Subscription Charges ($) | H1: Total IBM Revenue Contribution ($) | I1: Client Satisfaction Score | J1: Churned (Yes/No) | K1: Client Risk Score | L1: Predicted Client Lifetime Value ($) | M1: Cloud Platform Used | N1: AI Adoption Level | O1: Industry Sector | P1: Data Compliance Status | Q1: Bias Risk Score | R1: Data Security Level | S1: Analytics Tool Used | T1: Visualization Effectiveness Score | U1: Low Sat & High Risk | V1: Cluster Group | W1: Churned Count (1/0) | X1: Total IBM Revenue Contribution With Respect to Churned Clients | Y1: Average IBM Contributon | Z1: Maximum IBM Contributon | AA1: Minimum IBM Contributon | AB1: Median of IBM Contributon | AC1: Standard Deviation of IBM Contributon
A2: 38 | B2: Islamabad - IBM HQ | C2: 44238 | D2: =EDATE(C2,F2) -> 44541 | E2: 49.25 | F2: 10 | G2: 91.1 | H2: 179.08 | I2: 2 | J2: Yes | K2: 95 | L2: 3475 | M2: None | N2: Low | O2: Technology | P2: Compliant | Q2: 2 | R2: Low | S2: SQL | T2: 3 | U2: Yes | V2: 0 | W2: {=IF(J2:J151="Yes", 1, 0)} -> 1 | X2: =SUMIF(Dataset!$J$2:$J$151,"Yes",Dataset!$H$2:$H$151) -> 121780.87 | Y2: =AVERAGE(Dataset!$H$2:$H$151) -> 2086.9013 | Z2: =MAX(Dataset!$H$2:$H$151) -> 10690.92 | AA2: =MIN(Dataset!$H$2:$H$151) -> 25.2 | AB2: =MEDIAN(Dataset!$H$2:$H$151) -> 1363.745 | AC2: =_xlfn.STDEV.P(Dataset!$H$2:$H$151) -> 2298.5642
A3: 29 | B3: London - UK Branch | C3: 44149 | D3: =EDATE(C3,F3) -> 44544 | E3: 85.6 | F3: 13 | G3: 1345.55 | H3: 2024.3 | I3: 1 | J3: Yes | K3: 83 | L3: 4981 | M3: AWS | N3: Low | O3: Healthcare | P3: Compliant | Q3: 3 | R3: High | S3: Excel | T3: 8 | U3: Yes | V3: 1 | W3: 1
A4: 28 | B4: Sydney - Australia Pacific | C4: 44108 | D4: =EDATE(C4,F4) -> 44534 | E4: 86.85 | F4: 14 | G4: 220.95 | H4: 276.09 | I4: 2 | J4: No | K4: 70 | L4: 3561 | M4: None | N4: High | O4: Healthcare | P4: Compliant | Q4: 1 | R4: High | S4: SQL | T4: 8 | U4: No | V4: 0 | W4: 0
A5: 37 | B5: London - UK Branch | C5: 44375 | D5: =EDATE(C5,F5) -> 44558 | E5: 25.2 | F5: 6 | G5: 25.2 | H5: 25.2 | I5: 1 | J5: Yes | K5: 67 | L5: 5688 | M5: IBM Cloud | N5: High | O5: Finance | P5: Compliant | Q5: 2 | R5: Medium | S5: SQL | T5: 5 | U5: No | V5: 1 | W5: 1
A6: 30 | B6: Sydney - Australia Pacific | C6: 44549 | D6: =EDATE(C6,F6) -> 44549 | E6: 88.8 | F6: 0 | G6: 88.8 | H6: 148.4 | I6: 1 | J6: No | K6: 91 | L6: 3106 | M6: AWS | N6: High | O6: Technology | P6: Compliant | Q6: 2 | R6: Low | S6: IBM Cognos | T6: 10 | U6: Yes | V6: 0 | W6: 0
A7: 33 | B7: Islamabad - IBM HQ | C7: 44234 | D7: =EDATE(C7,F7) -> 44537 | E7: 74.4 | F7: 10 | G7: 1074.3 | H7: 1510.95 | I7: 1 | J7: Yes | K7: 86 | L7: 4616 | M7: None | N7: Low | O7: Healthcare | P7: Non-Compliant | Q7: 3 | R7: Medium | S7: Excel | T7: 2 | U7: Yes | V7: 2 | W7: 1
A8: 35 | B8: New York - US East | C8: 43883 | D8: =EDATE(C8,F8) -> 44552 | E8: 49.15 | F8: 22 | G8: 2550.9 | H8: 2580.9 | I8: 2 | J8: Yes | K8: 90 | L8: 5597 | M8: IBM Cloud | N8: Medium | O8: Technology | P8: Compliant | Q8: 4 | R8: High | S8: Power BI | T8: 7 | U8: Yes | V8: 1 | W8: 1
A9: 35 | B9: New York - US East | C9: 44427 | D9: =EDATE(C9,F9) -> 44549 | E9: 74.35 | F9: 4 | G9: 334.8 | H9: 563.6 | I9: 1 | J9: No | K9: 82 | L9: 5273 | M9: IBM Cloud | N9: Low | O9: Government | P9: Compliant | Q9: 1 | R9: Low | S9: Power BI | T9: 1 | U9: Yes | V9: 1 | W9: 0
A10: 26 | B10: London - UK Branch | C10: 43994 | D10: =EDATE(C10,F10) -> 44542 | E10: 30.35 | F10: 18 | G10: 1359.7 | H10: 1359.7 | I10: 1 | J10: Yes | K10: 96 | L10: 4829 | M10: IBM Cloud | N10: High | O10: Healthcare | P10: Compliant | Q10: 2 | R10: Low | S10: Power BI | T10: 1 | U10: Yes | V10: 2 | W10: 1
A11: 37 | B11: Toronto - Canada East | C11: 44243 | D11: =EDATE(C11,F11) -> 44546 | E11: 25.8 | F11: 10 | G11: 25.8 | H11: 45.8 | I11: 1 | J11: No | K11: 90 | L11: 3884 | M11: AWS | N11: Medium | O11: Finance | P11: Non-Compliant | Q11: 1 | R11: High | S11: Power BI | T11: 6 | U11: Yes | V11: 2 | W11: 0
A12: 25 | B12: Berlin - EU Central | C12: 44262 | D12: =EDATE(C12,F12) -> 44537 | E12: 110 | F12: 9 | G12: 4874.8 | H12: 4983.82 | I12: 1 | J12: Yes | K12: 81 | L12: 2403 | M12: AWS | N12: Low | O12: Government | P12: Compliant | Q12: 3 | R12: Low | S12: Excel | T12: 8 | U12: Yes | V12: 0 | W12: 1
A13: 37 | B13: Sydney - Australia Pacific | C13: 44508 | D13: =EDATE(C13,F13) -> 44538 | E13: 69.95 | F13: 1 | G13: 69.95 | H13: 102.45 | I13: 2 | J13: No | K13: 94 | L13: 3208 | M13: IBM Cloud | N13: High | O13: Retail | P13: Compliant | Q13: 3 | R13: High | S13: SQL | T13: 5 | U13: Yes | V13: 0 | W13: 0
A14: 38 | B14: San Francisco - US West | C14: 44027 | D14: =EDATE(C14,F14) -> 44545 | E14: 94.1 | F14: 17 | G14: 1782.4 | H14: 2837 | I14: 1 | J14: Yes | K14: 87 | L14: 2666 | M14: AWS | N14: Low | O14: Healthcare | P14: Compliant | Q14: 4 | R14: Medium | S14: Power BI | T14: 7 | U14: Yes | V14: 0 | W14: 1
... A151: 28 | B151: Sydney - Australia Pacific | C151: 44018 | D151: =EDATE(C151,F151) -> 44536 | E151: 70.55 | F151: 17 | G151: 70.55 | H151: 88.75 | I151: 3 | J151: No | K151: 82 | L151: 2146 | M151: IBM Cloud | N151: Low | O151: Finance | P151: Compliant | Q151: 5 | R151: Medium | S151: Excel | T151: 8 | U151: No | V151: 0 | W151: 0

Sheet Dashboard
A5: Sum of Total Subscription Charges ($) | B5: Industry Sector | N5: Region | O5: Count of Customers
A6: Region | B6: Finance | C6: Government | D6: Healthcare | E6: Retail | F6: Technology | G6: Grand Total | N6: Berlin - EU Central | O6: 15
A7: Berlin - EU Central | B7: 742.05 | C7: 12607.85 | D7: 8279.85 | E7: 4687.9 | F7: 74.7 | G7: 26392.35 | N7: Dubai - Middle East Hub | O7: 13
A8: Dubai - Middle East Hub | B8: 1622.45 | C8: 8418.65 | D8: 3246.3 | E8: 3586.45 | F8: 1253.05 | G8: 18126.9 | N8: Islamabad - IBM HQ | O8: 13
A9: Islamabad - IBM HQ | B9: 756.2 | C9: 1460.05 | D9: 1347.65 | E9: 5274.2 | F9: 2664.05 | G9: 11502.15 | N9: Karachi - South Asia | O9: 19
A10: Karachi - South Asia | B10: 5662.55 | C10: 6383.35 | D10: 7817.8 | E10: 1395.85 | F10: 17294.45 | G10: 38554 | N10: Lahore - Punjab Region | O10: 14
A11: Lahore - Punjab Region | B11: 2135.5 | C11: 11382.55 | D11: 6520 | E11: 6897.45 | F11: 2761.5 | G11: 29697 | N11: London - UK Branch | O11: 19
A12: London - UK Branch | B12: 1613.55 | C12: 4709.75 | D12: 14331.15 | E12: 3395.8 | F12: 840.1 | G12: 24890.35 | N12: New York - US East | O12: 17
A13: New York - US East | B13: 1383.2 | C13: 6820.8 | D13: 9758.5 | E13: 7361 | F13: 10438.95 | G13: 35762.45 | N13: San Francisco - US West | O13: 14
A14: San Francisco - US West | B14: 1027.3 | C14: 1899.65 | D14: 6050.05 | E14: 2562.15 | F14: 898.6 | G14: 12437.75 | N14: Sydney - Australia Pacific | O14: 17
A15: Sydney - Australia Pacific | B15: 10039.95 | C15: 3891.8 | D15: 3364.05 | E15: 362.75 | F15: 11256.95 | G15: 28915.5 | N15: Toronto - Canada East | O15: 9
A16: Toronto - Canada East | B16: 1919.75 | C16: 2675.85 | D16: 8069.1 | E16: 2155.25 | F16: 3105.55 | G16: 17925.5 | N16: Grand Total | O16: 150
A17: Grand Total | B17: 26902.5 | C17: 60250.3 | D17: 68784.45 | E17: 37678.8 | F17: 50587.9 | G17: 244203.95
A19: Sum of Total IBM Revenue Contribution ($) | B19: Column Labels | N19: Start Month | O19: Count of Customers
A20: Region | B20: Churned-No | C20: Churned-Yes | D20: Grand Total | N20: Jan | O20: 8
A21: Berlin - EU Central | B21: 15105.74 | C21: 15212.87 | D21: 30318.61 | N21: Feb | O21: 11
A22: Dubai - Middle East Hub | B22: 10699.99 | C22: 13730.09 | D22: 24430.08 | N22: Mar | O22: 16
A23: Islamabad - IBM HQ | B23: 8481.14 | C23: 5788.3 | D23: 14269.44 | N23: Apr | O23: 10
A24: Karachi - South Asia | B24: 35673.97 | C24: 14116.65 | D24: 49790.62 | N24: May | O24: 15
A25: Lahore - Punjab Region | B25: 20236.54 | C25: 18518.05 | D25: 38754.59 | N25: Jun | O25: 11
A26: London - UK Branch | B26: 23844.18 | C26: 5838.66 | D26: 29682.84 | N26: Jul | O26: 9
A27: New York - US East | B27: 26405.33 | C27: 20613.49 | D27: 47018.82 | N27: Aug | O27: 11
A28: San Francisco - US West | B28: 7625.41 | C28: 9092.35 | D28: 16717.76 | N28: Sep | O28: 13
A29: Sydney - Australia Pacific | B29: 22110.79 | C29: 16082.96 | D29: 38193.75 | N29: Oct | O29: 19
A30: Toronto - Canada East | B30: 21071.24 | C30: 2787.45 | D30: 23858.69 | N30: Nov | O30: 19
A31: Grand Total | B31: 191254.33 | C31: 121780.87 | D31: 313035.2 | N31: Dec | O31: 8
N32: Grand Total | O32: 150
A33: AI Adoption Level | B33: Sum of Total IBM Revenue Contribution ($)
A34: High | B34: 87580.68 | J34: Industry Sector | K34: Average of Client Satisfaction Score
A35: Low | B35: 123670.32 | J35: Finance | K35: 1.76
A36: Medium | B36: 101784.2 | J36: Government | K36: 1.59375
A37: Grand Total | B37: 313035.2 | J37: Healthcare | K37: 1.6585366
J38: Retail | K38: 1.7619048
J39: Technology | K39: 1.8709677
J40: Grand Total | K40: 1.72
J41: Industry Sector | K41: Sum of Total IBM Revenue Contribution ($)
J42: Healthcare | K42: 89826.77
J43: Government | K43: 75013.68
J44: Technology | K44: 65558.56
J45: Retail | K45: 47019.04
...

Sheet AB Testing
A1: Churned – Yes | B1: Churned – No | C1: p-value | D1: Average
A2: 4616 | B2: 5433 | C2: =_xlfn.T.TEST(A2:A57,B2:B95,2,3) -> 0.35910938 | D2: =AVERAGE(A2:A57) -> 4292.75
A3: 2314 | B3: 5302 | D3: =AVERAGE(B2:B95) -> 4108
A4: 4778 | B4: 3179
A5: 2927 | B5: 5337
A6: 4902 | B6: 2793
A7: 2666 | B7: 4638
A8: 4517 | B8: 3964
A9: 5808 | B9: 5444
A10: 4880 | B10: 5717
A11: 2728 | B11: 4419
A12: 5604 | B12: 5980
A13: 2065 | B13: 5828
A14: 5432 | B14: 2494
A15: 5597 | B15: 3810
... A57: 5573 | B57: 4193
B58: 5745
B59: 4028
B60: 4458
B61: 5683
B62: 3348
B63: 3884
B64: 5374
B65: 3106
B66: 3861
B67: 2740
B68: 4871
B69: 5001
... B95: 5676
